start time at:2020-03-29 15:19:22
2020-03-29 15:19:27 an error has occurred...
Traceback (most recent call last):
  File "/home/develop/jinGame/jin_agent.py", line 935, in process
    raise ValueError("error!")
ValueError: error!

During handling of the above exception, another exception occurred:

Traceback (most recent call last):
  File "jin_execute.py", line 32, in main
    jin_agent.main()
  File "/home/develop/jinGame/jin_agent.py", line 967, in main
    res = agent.process(env)
  File "/home/develop/jinGame/jin_agent.py", line 957, in process
    df = pd.DataFrame(df_Logs)
  File "/usr/local/lib/python3.6/dist-packages/pandas/core/frame.py", line 435, in __init__
    mgr = init_dict(data, index, columns, dtype=dtype)
  File "/usr/local/lib/python3.6/dist-packages/pandas/core/internals/construction.py", line 254, in init_dict
    return arrays_to_mgr(arrays, data_names, index, columns, dtype=dtype)
  File "/usr/local/lib/python3.6/dist-packages/pandas/core/internals/construction.py", line 64, in arrays_to_mgr
    index = extract_index(arrays)
  File "/usr/local/lib/python3.6/dist-packages/pandas/core/internals/construction.py", line 365, in extract_index
    raise ValueError("arrays must all be same length")
ValueError: arrays must all be same length
